Workbook
Name Clothing: Sheet3!$F$3:$F$5
Name Electronics: Sheet3!$E$3:$E$5
Name Furniture: Sheet3!$C$3:$C$5
Name Laptop: CHOOSE(Sheet1!XEZ1048567,Furniture,Clothing,Office_Supplies,Electronics)
Name Office_Supplies: Sheet3!$D$3:$D$5
Name Slicer_Month: #N/A
Name Slicer_Year: #N/A
Name Sub_Category: _xlfn.UNIQUE(_xlfn._xlws.FILTER(Sales_Data!E4:E2202,Sales_Data!D4:D2202=Sheet3!XFC1048576,"NA"))

Sheet Sales_Data
A1: Order ID | B1: Order Date | C1: State | D1: City | E1: Category | F1: Sub Category | G1: Sales | H1: Profit | I1: Quantity | J1: Customer Type | K1: Payment Mode | L1: Profit Margin % | M1: Top Category Sales | N1: Loss Orders Count | O1: Month | P1: Year
A2: ORD00001 | B2: 45387 | C2: Florida | D2: Miami | E2: Furniture | F2: Table | G2: 14526 | H2: 3910.53 | I2: 8 | J2: Returning | K2: UPI | L2: =H2/G2 -> 0.269209 | M2: =IF(E2="Clothing",G2,0) -> 0 | N2: =IF(H2<0,1,0) -> 0 | O2: =TEXT(B2,"MMM") -> Apr | P2: =TEXT(B2,"YYYY") -> 2024
A3: ORD00002 | B3: 45318 | C3: Illinois | D3: Chicago | E3: Clothing | F3: Jacket | G3: 16387 | H3: -2579.2 | I3: 6 | J3: New | K3: Net Banking | L3: =H3/G3 -> -0.15739306 | M3: =IF(E3="Clothing",G3,0) -> 16387 | N3: =IF(H3<0,1,0) -> 1 | O3: =TEXT(B3,"MMM") -> Jan | P3: =TEXT(B3,"YYYY") -> 2024
A4: ORD00003 | B4: 45355 | C4: Illinois | D4: Chicago | E4: Office Supplies | F4: Pen | G4: 33361 | H4: 2518.17 | I4: 7 | J4: Returning | K4: Net Banking | L4: =H4/G4 -> 0.07548245 | M4: =IF(E4="Clothing",G4,0) -> 0 | N4: =IF(H4<0,1,0) -> 0 | O4: =TEXT(B4,"MMM") -> Mar | P4: =TEXT(B4,"YYYY") -> 2024
A5: ORD00004 | B5: 45213 | C5: Illinois | D5: Springfield | E5: Office Supplies | F5: Notebook | G5: 14224 | H5: -2444.98 | I5: 3 | J5: Returning | K5: UPI | L5: =H5/G5 -> -0.17189117 | M5: =IF(E5="Clothing",G5,0) -> 0 | N5: =IF(H5<0,1,0) -> 1 | O5: =TEXT(B5,"MMM") -> Oct | P5: =TEXT(B5,"YYYY") -> 2023
A6: ORD00005 | B6: 45445 | C6: New York | D6: New York City | E6: Electronics | F6: Accessories | G6: 10335 | H6: 1493.17 | I6: 9 | J6: New | K6: Cash | L6: =H6/G6 -> 0.14447702 | M6: =IF(E6="Clothing",G6,0) -> 0 | N6: =IF(H6<0,1,0) -> 0 | O6: =TEXT(B6,"MMM") -> Jun | P6: =TEXT(B6,"YYYY") -> 2024
A7: ORD00006 | B7: 45355 | C7: New York | D7: Buffalo | E7: Furniture | F7: Chair | G7: 43379 | H7: 8340.85 | I7: 8 | J7: Returning | K7: Net Banking | L7: =H7/G7 -> 0.19227852 | M7: =IF(E7="Clothing",G7,0) -> 0 | N7: =IF(H7<0,1,0) -> 0 | O7: =TEXT(B7,"MMM") -> Mar | P7: =TEXT(B7,"YYYY") -> 2024
A8: ORD00007 | B8: 45052 | C8: New York | D8: New York City | E8: Furniture | F8: Sofa | G8: 32008 | H8: 7338.89 | I8: 7 | J8: New | K8: UPI | L8: =H8/G8 -> 0.22928299 | M8: =IF(E8="Clothing",G8,0) -> 0 | N8: =IF(H8<0,1,0) -> 0 | O8: =TEXT(B8,"MMM") -> May | P8: =TEXT(B8,"YYYY") -> 2023
A9: ORD00008 | B9: 45367 | C9: Texas | D9: Houston | E9: Office Supplies | F9: Stapler | G9: 15680 | H9: -562.98 | I9: 8 | J9: Corporate | K9: Card | L9: =H9/G9 -> -0.035904337 | M9: =IF(E9="Clothing",G9,0) -> 0 | N9: =IF(H9<0,1,0) -> 1 | O9: =TEXT(B9,"MMM") -> Mar | P9: =TEXT(B9,"YYYY") -> 2024
A10: ORD00009 | B10: 45226 | C10: Texas | D10: Dallas | E10: Clothing | F10: Jeans | G10: 41719 | H10: 13940.39 | I10: 8 | J10: New | K10: UPI | L10: =H10/G10 -> 0.33414967 | M10: =IF(E10="Clothing",G10,0) -> 41719 | N10: =IF(H10<0,1,0) -> 0 | O10: =TEXT(B10,"MMM") -> Oct | P10: =TEXT(B10,"YYYY") -> 2023
A11: ORD00010 | B11: 45604 | C11: Illinois | D11: Springfield | E11: Office Supplies | F11: Stapler | G11: 49853 | H11: -4347.44 | I11: 1 | J11: Returning | K11: Cash | L11: =H11/G11 -> -0.087205183 | M11: =IF(E11="Clothing",G11,0) -> 0 | N11: =IF(H11<0,1,0) -> 1 | O11: =TEXT(B11,"MMM") -> Nov | P11: =TEXT(B11,"YYYY") -> 2024
A12: ORD00011 | B12: 45252 | C12: Florida | D12: Orlando | E12: Electronics | F12: Accessories | G12: 36437 | H12: -3538.05 | I12: 7 | J12: New | K12: Net Banking | L12: =H12/G12 -> -0.097100475 | M12: =IF(E12="Clothing",G12,0) -> 0 | N12: =IF(H12<0,1,0) -> 1 | O12: =TEXT(B12,"MMM") -> Nov | P12: =TEXT(B12,"YYYY") -> 2023
A13: ORD00012 | B13: 45650 | C13: California | D13: San Francisco | E13: Furniture | F13: Table | G13: 18532 | H13: 4943.89 | I13: 10 | J13: Corporate | K13: Card | L13: =H13/G13 -> 0.26677585 | M13: =IF(E13="Clothing",G13,0) -> 0 | N13: =IF(H13<0,1,0) -> 0 | O13: =TEXT(B13,"MMM") -> Dec | P13: =TEXT(B13,"YYYY") -> 2024
... A548: ORD00547 | B548: 45261 | C548: California | D548: Los Angeles | E548: Furniture | F548: Chair | G548: 23808 | H548: 4823.58 | I548: 6 | J548: New | K548: Card | L548: =H548/G548 -> 0.20260333 | M548: =IF(E548="Clothing",G548,0) -> 0 | N548: =IF(H548<0,1,0) -> 0 | O548: =TEXT(B548,"MMM") -> Dec | P548: =TEXT(B548,"YYYY") -> 2023
A549: ORD00548 | B549: 45225 | C549: New York | D549: New York City | E549: Electronics | F549: Accessories | G549: 46206 | H549: 10203.74 | I549: 5 | J549: Corporate | K549: Cash | L549: =H549/G549 -> 0.22083149 | M549: =IF(E549="Clothing",G549,0) -> 0 | N549: =IF(H549<0,1,0) -> 0 | O549: =TEXT(B549,"MMM") -> Oct | P549: =TEXT(B549,"YYYY") -> 2023 | R549: Karnataka
A550: ORD00549 | B550: 45374 | C550: Texas | D550: Houston | E550: Electronics | F550: Mobile | G550: 2453 | H550: 797.95 | I550: 5 | J550: Corporate | K550: Card | L550: =H550/G550 -> 0.32529556 | M550: =IF(E550="Clothing",G550,0) -> 0 | N550: =IF(H550<0,1,0) -> 0 | O550: =TEXT(B550,"MMM") -> Mar | P550: =TEXT(B550,"YYYY") -> 2024 | R550: Florida
A551: ORD00550 | B551: 45434 | C551: Florida | D551: Orlando | E551: Office Supplies | F551: Pen | G551: 38644 | H551: -6367.61 | I551: 5 | J551: Returning | K551: Cash | L551: =H551/G551 -> -0.16477616 | M551: =IF(E551="Clothing",G551,0) -> 0 | N551: =IF(H551<0,1,0) -> 1 | O551: =TEXT(B551,"MMM") -> May | P551: =TEXT(B551,"YYYY") -> 2024 | R551: Gujarat
A552: ORD00551 | B552: 45563 | C552: New York | D552: New York City | E552: Furniture | F552: Table | G552: 12548 | H552: 3581.35 | I552: 3 | J552: Returning | K552: Card | L552: =H552/G552 -> 0.28541202 | M552: =IF(E552="Clothing",G552,0) -> 0 | N552: =IF(H552<0,1,0) -> 0 | O552: =TEXT(B552,"MMM") -> Sep | P552: =TEXT(B552,"YYYY") -> 2024 | R552: Gujarat
A553: ORD00552 | B553: 45521 | C553: Illinois | D553: Chicago | E553: Office Supplies | F553: Pen | G553: 34338 | H553: 8813.23 | I553: 4 | J553: Corporate | K553: UPI | L553: =H553/G553 -> 0.25666113 | M553: =IF(E553="Clothing",G553,0) -> 0 | N553: =IF(H553<0,1,0) -> 0 | O553: =TEXT(B553,"MMM") -> Aug | P553: =TEXT(B553,"YYYY") -> 2024 | R553: Florida
A554: ORD00553 | B554: 45327 | C554: New York | D554: Buffalo | E554: Furniture | F554: Chair | G554: 47754 | H554: -5066.89 | I554: 4 | J554: Returning | K554: Card | L554: =H554/G554 -> -0.10610399 | M554: =IF(E554="Clothing",G554,0) -> 0 | N554: =IF(H554<0,1,0) -> 1 | O554: =TEXT(B554,"MMM") -> Feb | P554: =TEXT(B554,"YYYY") -> 2024 | R554: Delhi
A555: ORD00554 | B555: 45614 | C555: Texas | D555: Houston | E555: Electronics | F555: Laptop | G555: 36860 | H555: 3906.86 | I555: 2 | J555: Corporate | K555: Cash | L555: =H555/G555 -> 0.10599186 | M555: =IF(E555="Clothing",G555,0) -> 0 | N555: =IF(H555<0,1,0) -> 0 | O555: =TEXT(B555,"MMM") -> Nov | P555: =TEXT(B555,"YYYY") -> 2024 | R555: Karnataka
A556: ORD00555 | B556: 45095 | C556: California | D556: San Francisco | E556: Office Supplies | F556: Pen | G556: 44932 | H556: 2171.88 | I556: 2 | J556: Corporate | K556: Net Banking | L556: =H556/G556 -> 0.048337043 | M556: =IF(E556="Clothing",G556,0) -> 0 | N556: =IF(H556<0,1,0) -> 0 | O556: =TEXT(B556,"MMM") -> Jun | P556: =TEXT(B556,"YYYY") -> 2023
A557: ORD00556 | B557: 45122 | C557: Florida | D557: Orlando | E557: Clothing | F557: Jeans | G557: 32785 | H557: -5187.71 | I557: 8 | J557: New | K557: Card | L557: =H557/G557 -> -0.15823425 | M557: =IF(E557="Clothing",G557,0) -> 32785 | N557: =IF(H557<0,1,0) -> 1 | O557: =TEXT(B557,"MMM") -> Jul | P557: =TEXT(B557,"YYYY") -> 2023
A558: ORD00557 | B558: 45262 | C558: Texas | D558: Houston | E558: Office Supplies | F558: Stapler | G558: 11795 | H558: 489.85 | I558: 8 | J558: New | K558: Card | L558: =H558/G558 -> 0.041530309 | M558: =IF(E558="Clothing",G558,0) -> 0 | N558: =IF(H558<0,1,0) -> 0 | O558: =TEXT(B558,"MMM") -> Dec | P558: =TEXT(B558,"YYYY") -> 2023
A559: ORD00558 | B559: 44945 | C559: Texas | D559: Dallas | E559: Electronics | F559: Mobile | G559: 13150 | H559: 3364.51 | I559: 1 | J559: New | K559: Net Banking | L559: =H559/G559 -> 0.25585627 | M559: =IF(E559="Clothing",G559,0) -> 0 | N559: =IF(H559<0,1,0) -> 0 | O559: =TEXT(B559,"MMM") -> Jan | P559: =TEXT(B559,"YYYY") -> 2023
A560: ORD00559 | B560: 45349 | C560: Florida | D560: Miami | E560: Furniture | F560: Chair | G560: 25840 | H560: -1432.53 | I560: 1 | J560: New | K560: Net Banking | L560: =H560/G560 -> -0.055438467 | M560: =IF(E560="Clothing",G560,0) -> 0 | N560: =IF(H560<0,1,0) -> 1 | O560: =TEXT(B560,"MMM") -> Feb | P560: =TEXT(B560,"YYYY") -> 2024
A561: ORD00560 | B561: 45276 | C561: New York | D561: New York City | E561: Office Supplies | F561: Notebook | G561: 43285 | H561: 1784.9 | I561: 7 | J561: Returning | K561: Cash | L561: =H561/G561 -> 0.041235994 | M561: =IF(E561="Clothing",G561,0) -> 0 | N561: =IF(H561<0,1,0) -> 0 | O561: =TEXT(B561,"MMM") -> Dec | P561: =TEXT(B561,"YYYY") -> 2023
A562: ORD00561 | B562: 45014 | C562: New York | D562: New York City | E562: Furniture | F562: Chair | G562: 39682 | H562: -3876.55 | I562: 1 | J562: Returning | K562: Cash | L562: =H562/G562 -> -0.097690389 | M562: =IF(E562="Clothing",G562,0) -> 0 | N562: =IF(H562<0,1,0) -> 1 | O562: =TEXT(B562,"MMM") -> Mar | P562: =TEXT(B562,"YYYY") -> 2023
A563: ORD00562 | B563: 45640 | C563: Texas | D563: Houston | E563: Office Supplies | F563: Pen | G563: 27868 | H563: 8314.49 | I563: 6 | J563: Returning | K563: Card | L563: =H563/G563 -> 0.29835259 | M563: =IF(E563="Clothing",G563,0) -> 0 | N563: =IF(H563<0,1,0) -> 0 | O563: =TEXT(B563,"MMM") -> Dec | P563: =TEXT(B563,"YYYY") -> 2024
A564: ORD00563 | B564: 45223 | C564: California | D564: Los Angeles | E564: Office Supplies | F564: Notebook | G564: 18040 | H564: -3367.09 | I564: 4 | J564: New | K564: Net Banking | L564: =H564/G564 -> -0.18664579 | M564: =IF(E564="Clothing",G564,0) -> 0 | N564: =IF(H564<0,1,0) -> 1 | O564: =TEXT(B564,"MMM") -> Oct | P564: =TEXT(B564,"YYYY") -> 2023
A565: ORD00564 | B565: 45322 | C565: Illinois | D565: Chicago | E565: Clothing | F565: Jacket | G565: 23723 | H565: 4187.64 | I565: 1 | J565: New | K565: Card | L565: =H565/G565 -> 0.17652236 | M565: =IF(E565="Clothing",G565,0) -> 23723 | N565: =IF(H565<0,1,0) -> 0 | O565: =TEXT(B565,"MMM") -> Jan | P565: =TEXT(B565,"YYYY") -> 2024
A566: ORD00565 | B566: 45500 | C566: New York | D566: Buffalo | E566: Furniture | F566: Chair | G566: 38952 | H566: 1076.78 | I566: 3 | J566: New | K566: Card | L566: =H566/G566 -> 0.027643767 | M566: =IF(E566="Clothing",G566,0) -> 0 | N566: =IF(H566<0,1,0) -> 0 | O566: =TEXT(B566,"MMM") -> Jul | P566: =TEXT(B566,"YYYY") -> 2024
A567: ORD00566 | B567: 45443 | C567: Illinois | D567: Chicago | E567: Office Supplies | F567: Pen | G567: 39310 | H567: 2228.99 | I567: 1 | J567: Returning | K567: UPI | L567: =H567/G567 -> 0.056702875 | M567: =IF(E567="Clothing",G567,0) -> 0 | N567: =IF(H567<0,1,0) -> 0 | O567: =TEXT(B567,"MMM") -> May | P567: =TEXT(B567,"YYYY") -> 2024
... A2201: ORD02200 | B2201: 45335 | C2201: Texas | D2201: Houston | E2201: Clothing | F2201: Jacket | G2201: 40952 | H2201: 12372.54 | I2201: 7 | J2201: Corporate | K2201: Cash | L2201: =H2201/G2201 -> 0.30212297 | M2201: =IF(E2201="Clothing",G2201,0) -> 40952 | N2201: =IF(H2201<0,1,0) -> 0 | O2201: =TEXT(B2201,"MMM") -> Feb | P2201: =TEXT(B2201,"YYYY") -> 2024

Sheet Pivot Table
A1: TASK 1 – KPI Dashboard
D3: Total Profit | E3: =GETPIVOTDATA("Profit",$D$4) -> 3996604.5 | G3: Profit Margin % | H3: =GETPIVOTDATA("Profit Margin %",$G$4) -> 0.073566533 | J3: Total Sales | K3: =GETPIVOTDATA("Sales",$J$4) -> 54877614
A4: Excel Dashboard banao jisme ye KPIs ho: | D4: Row Labels | E4: Sum of Profit | G4: Row Labels | H4: Average of Profit Margin % | J4: Row Labels | K4: Sum of Sales
D5: Jan | E5: 385182.43 | G5: Jan | H5: 0.071568745 | J5: Jan | K5: 5197487
A6: Use: | D6: Feb | E6: 282990.67 | G6: Feb | H6: 0.078770147 | J6: Feb | K6: 4361142
A7: Pivot Table | D7: Mar | E7: 330156.25 | G7: Mar | H7: 0.065922075 | J7: Mar | K7: 5032041
A8: Slicers | D8: Apr | E8: 282357.26 | G8: Apr | H8: 0.07568041 | J8: Apr | K8: 3804003
A9: Timeline | D9: May | E9: 295179.42 | G9: May | H9: 0.074295534 | J9: May | K9: 4334978
D10: Jun | E10: 339567.42 | G10: Jun | H10: 0.073560341 | J10: Jun | K10: 4225541
D11: Jul | E11: 208821.71 | G11: Jul | H11: 0.0517195 | J11: Jul | K11: 4630354 | O11: Row Labels | P11: Sum of Profit
D12: Aug | E12: 405885.23 | G12: Aug | H12: 0.085555619 | J12: Aug | K12: 4606162 | O12: Florida | P12: 701237.22
D13: Sep | E13: 397131.93 | G13: Sep | H13: 0.067305718 | J13: Sep | K13: 5117094 | O13: Illinois | P13: 1012340
D14: Oct | E14: 371649.12 | G14: Oct | H14: 0.080978067 | J14: Oct | K14: 4649238 | O14: New York | P14: 749378.44
D15: Nov | E15: 391190.1 | G15: Nov | H15: 0.083957172 | J15: Nov | K15: 4314504 | O15: Texas | P15: 827231.89
D16: Dec | E16: 306492.91 | G16: Dec | H16: 0.076096742 | J16: Dec | K16: 4605070 | O16: California | P16: 706416.9
D17: Grand Total | E17: 3996604.5 | G17: Grand Total | H17: 0.073566533 | J17: Grand Total | K17: 54877614 | O17: Grand Total | P17: 3996604.5
A19: Loss Orders Count | B19: =GETPIVOTDATA("Loss Orders Count",$A$20) -> 812 | D19: Top Category Sales
A20: Row Labels | B20: Loss Orders Count | D20: Row Labels | E20: Sum of Profit | G20: Avg Order Value | H20: =GETPIVOTDATA("Sales",$G$21) -> 24944.37 | J20: Total Order | K20: =GETPIVOTDATA("Order ID",$J$21) -> 2200 | N20: Month | O20: Sum of Quantity
A21: Jan | B21: 78 | D21: Clothing | E21: 1019254.3 | G21: Row Labels | H21: Average of Sales | J21: Row Labels | K21: Count of Order ID | N21: Corporate | O21: 3844
A22: Feb | B22: 67 | D22: Electronics | E22: 1013037.4 | G22: Jan | H22: 27211.974 | J22: Jan | K22: 191 | N22: New | O22: 4100
A23: Mar | B23: 78 | D23: Office Supplies | E23: 998768.65 | G23: Feb | H23: 23962.319 | J23: Feb | K23: 182 | N23: Returning | O23: 4022
A24: Apr | B24: 60 | D24: Furniture | E24: 965544.1 | G24: Mar | H24: 25286.638 | J24: Mar | K24: 199 | N24: Grand Total | O24: 11966
A25: May | B25: 64 | D25: Grand Total | E25: 3996604.5 | G25: Apr | H25: 24075.968 | J25: Apr | K25: 158
A26: Jun | B26: 60 | G26: May | H26: 24771.303 | J26: May | K26: 175
A27: Jul | B27: 74 | G27: Jun | H27: 24145.949 | J27: Jun | K27: 175
A28: Aug | B28: 60 | G28: Jul | H28: 25028.941 | J28: Jul | K28: 185
A29: Sep | B29: 83 | G29: Aug | H29: 25589.789 | J29: Aug | K29: 180
A30: Oct | B30: 65 | G30: Sep | H30: 24720.261 | J30: Sep | K30: 207
A31: Nov | B31: 59 | G31: Oct | H31: 24862.235 | J31: Oct | K31: 187
A32: Dec | B32: 64 | G32: Nov | H32: 24654.309 | J32: Nov | K32: 175
A33: Grand Total | B33: 812 | G33: Dec | H33: 24758.441 | J33: Dec | K33: 186
G34: Grand Total | H34: 24944.37 | J34: Grand Total | K34: 2200
A36: TASK 2 – Profitability Analysis
A38: Kaunsi Category sabse zyada loss kar rahi hai? | D38: Kaunsa State high sales but low profit? | H38: Negative profit wali top 10 rows nikaalo.
A39: Row Labels | B39: Sum of Profit | D39: Row Labels | E39: Sum of Profit | F39: Sum of Sales | H39: Row Labels | I39: Sum of Profit
A40: Clothing | B40: 1019254.3 | D40: New York | E40: 749378.44 | F40: 11486858 | H40: ORD00047 | I40: -9029.27
A41: Electronics | B41: 1013037.4 | D41: Illinois | E41: 1012340 | F41: 11236804 | H41: ORD00308 | I41: -9083.17
A42: Furniture | B42: 965544.1 | D42: Texas | E42: 827231.89 | F42: 11183948 | H42: ORD00631 | I42: -8683.6
A43: Office Supplies | B43: 998768.65 | D43: Florida | E43: 701237.22 | F43: 11025179 | H43: ORD00677 | I43: -8705
A44: Grand Total | B44: 3996604.5 | D44: California | E44: 706416.9 | F44: 9944825 | H44: ORD00824 | I44: -8738.25
...

Sheet Dashboard
A106: =GETPIVOTDATA("Order ID",'Pivot Table'!$J$21) -> 2200

Sheet Sheet1
A1: 4
A3: Delhi | B3: 1090365
A4: Gujarat | B4: 359178
A5: Karnataka | B5: 726455
A6: Maharashtra | B6: 1003250
A7: Uttar Pradesh | B7: 1051620
E12: State | F12: City1 | G12: City2
E13: California | F13: Los Angeles | G13: San Francisco | I13: IF(RANDBETWEEN(1,2)=1, XLOOKUP(A2,Sheet2!A:A,Sheet2!B:B), XLOOKUP(A2,Sheet2!A:A,Sheet2!C:C))
E14: Texas | F14: Houston | G14: Dallas
E15: Florida | F15: Miami | G15: Orlando
E16: New York | F16: New York City | G16: Buffalo
E17: Illinois | F17: Chicago | G17: Springfield
E19: State | F19: City | G19: Sales | I19: Row Labels | J19: Sum of Sales | M19: Row Labels | N19: Sum of Sales | O19: Sum of Profit
E20: Florida | F20: Miami | G20: 531995 | I20: Jan | J20: 5197487 | M20: {=I20:I31} -> Jan | N20: =GETPIVOTDATA("Sum of Sales",$I$19,"Month",I20) -> 5197487 | O20: {=K20:K31} -> 0
E21: Florida | F21: Orlando | G21: 519625 | I21: Feb | J21: 4361142 | M21: Feb | N21: =GETPIVOTDATA("Sum of Sales",$I$19,"Month",I21) -> 4361142 | O21: 0
E22: Illinois | F22: Chicago | G22: 577053 | I22: Mar | J22: 5032041 | M22: Mar | N22: =GETPIVOTDATA("Sum of Sales",$I$19,"Month",I22) -> 5032041 | O22: 0
E23: Illinois | F23: Springfield | G23: 426197 | I23: Apr | J23: 3804003 | M23: Apr | N23: =GETPIVOTDATA("Sum of Sales",$I$19,"Month",I23) -> 3804003 | O23: 0
E24: New York | F24: New York City | G24: 361236 | I24: May | J24: 4334978 | M24: May | N24: =GETPIVOTDATA("Sum of Sales",$I$19,"Month",I24) -> 4334978 | O24: 0
E25: New York | F25: Buffalo | G25: 729129 | I25: Jun | J25: 4225541 | M25: Jun | N25: =GETPIVOTDATA("Sum of Sales",$I$19,"Month",I25) -> 4225541 | O25: 0
E26: Texas | F26: Houston | G26: 350958 | I26: Jul | J26: 4630354 | M26: Jul | N26: =GETPIVOTDATA("Sum of Sales",$I$19,"Month",I26) -> 4630354 | O26: 0
E27: Texas | F27: Dallas | G27: 375497 | I27: Aug | J27: 4606162 | M27: Aug | N27: =GETPIVOTDATA("Sum of Sales",$I$19,"Month",I27) -> 4606162 | O27: 0
E28: California | F28: San Francisco | G28: 217119 | I28: Sep | J28: 5117094 | M28: Sep | N28: =GETPIVOTDATA("Sum of Sales",$I$19,"Month",I28) -> 5117094 | O28: 0
E29: California | F29: Los Angeles | G29: 142059 | I29: Oct | J29: 4649238 | M29: Oct | N29: =GETPIVOTDATA("Sum of Sales",$I$19,"Month",I29) -> 4649238 | O29: 0
I30: Nov | J30: 4314504 | M30: Nov | N30: =GETPIVOTDATA("Sum of Sales",$I$19,"Month",I30) -> 4314504 | O30: 0
I31: Dec | J31: 4605070 | M31: Dec | N31: =GETPIVOTDATA("Sum of Sales",$I$19,"Month",I31) -> 4605070 | O31: 0
I32: Grand Total | J32: 54877614

Sheet Sheet3
C1: Furniture | D1: Office Supplies | E1: Electronics | F1: Clothing
C3: {=_xlfn.UNIQUE(_xlfn._xlws.FILTER(Sales_Data!F3:F2201,Sales_Data!E3:E2201=C$1,"NA"))} -> Chair | D3: {=_xlfn.UNIQUE(_xlfn._xlws.FILTER(Sales_Data!F3:F2201,Sales_Data!E3:E2201=D$1,"NA"))} -> Pen | E3: {=_xlfn.UNIQUE(_xlfn._xlws.FILTER(Sales_Data!F3:F2201,Sales_Data!E3:E2201=E$1,"NA"))} -> Accessories | F3: {=_xlfn.UNIQUE(_xlfn._xlws.FILTER(Sales_Data!F3:F2201,Sales_Data!E3:E2201=F$1,"NA"))} -> Jacket
C4: Sofa | D4: Notebook | E4: Laptop | F4: Jeans
C5: Table | D5: Stapler | E5: Mobile | F5: Shirt
E8: {=CHOOSE(Sheet1!A1,Furniture,Clothing,Office_Supplies,Electronics)} -> Accessories
E9: Laptop
E10: Mobile
